using System;
using System.Runtime.ExceptionServices;
using System.Threading.Tasks;

namespace Saver2.Helpers
{
    public static class TryWithAwaitInCatch
    {
        public static async Task ExecuteAndHandleErrorAsync(Func<Task> actionAsync,
            Func<Exception, Task<bool>> errorHandlerAsync)
        {
            ExceptionDispatchInfo capturedException = null;
            try
            {
                await actionAsync().ConfigureAwait(false);
            }
            catch (Exception ex)
            {
                capturedException = ExceptionDispatchInfo.Capture(ex);
            }

            if (capturedException != null)
            {
                bool needsThrow = await errorHandlerAsync(capturedException.SourceException).ConfigureAwait(false);
                if (needsThrow)
                {
                    capturedException.Throw();
                }
            }
        }
    }
}